Workbook

Sheet COMPARATIVO ANUAL
A1: COMPARATIVO ANUAL — 2025 vs 2026 | Bela Cereais Grupo
A2: Indicador | B2: 2025 | C2: 2026 | D2: Variação (R$) | E2: Variação (%)
A3: Lucro Bruto (Contratos) | B3: =SUMIF(BD_LUCRO!B2:B211,2025,BD_LUCRO!K2:K211) -> 6965952.7 | C3: =SUMIF(BD_LUCRO!B2:B211,2026,BD_LUCRO!K2:K211) -> 1831062.6 | D3: =C3-B3 -> -5134890 | E3: =IF(B3<>0,(C3-B3)/ABS(B3),0) -> -0.7371411
A4: (-) Total Frete | B4: =-SUMIF(BD_LUCRO!B2:B211,2025,BD_LUCRO!L2:L211) -> -3259171.8 | C4: =-SUMIF(BD_LUCRO!B2:B211,2026,BD_LUCRO!L2:L211) -> -163687 | D4: =C4-B4 -> 3095484.8 | E4: =IF(B4<>0,(C4-B4)/ABS(B4),0) -> 0.9497765
A5: (-) Impostos sobre contratos | B5: =-SUMIF(BD_LUCRO!B2:B211,2025,BD_LUCRO!M2:M211) -> -7281.97 | C5: =-SUMIF(BD_LUCRO!B2:B211,2026,BD_LUCRO!M2:M211) -> -65961.45 | D5: =C5-B5 -> -58679.48 | E5: =IF(B5<>0,(C5-B5)/ABS(B5),0) -> -8.0581876
A6: (-) Comissões | B6: =-SUMIF(BD_LUCRO!B2:B211,2025,BD_LUCRO!N2:N211) -> -1826139.8 | C6: =-SUMIF(BD_LUCRO!B2:B211,2026,BD_LUCRO!N2:N211) -> -192725.19 | D6: =C6-B6 -> 1633414.6 | E6: =IF(B6<>0,(C6-B6)/ABS(B6),0) -> 0.89446307
A7: (=) Lucro Líquido Operacional | B7: =SUMIF(BD_LUCRO!B2:B211,2025,BD_LUCRO!P2:P211) -> 4200075.4 | C7: =SUMIF(BD_LUCRO!B2:B211,2026,BD_LUCRO!P2:P211) -> 1427661.2 | D7: =C7-B7 -> -2772414.3 | E7: =IF(B7<>0,(C7-B7)/ABS(B7),0) -> -0.66008678
A8: (-) Despesas Administrativas | B8: =-SUMIF(BD_DESP!B2:B759,2025,BD_DESP!E2:E759) -> -3677506.7 | C8: =-SUMIF(BD_DESP!B2:B759,2026,BD_DESP!E2:E759) -> -1334005.8 | D8: =C8-B8 -> 2343500.9 | E8: =IF(B8<>0,(C8-B8)/ABS(B8),0) -> 0.63725265
A9: (=) LUCRO LÍQUIDO FINAL | B9: =B7+B8 -> 522568.7 | C9: =C7+C8 -> 93655.32 | D9: =C9-B9 -> -428913.38 | E9: =IF(B9<>0,(C9-B9)/ABS(B9),0) -> -0.82077893
A11: Peso Total (Kg) | B11: =SUMIF(BD_LUCRO!B2:B211,2025,BD_LUCRO!I2:I211) -> 25716499 | C11: =SUMIF(BD_LUCRO!B2:B211,2026,BD_LUCRO!I2:I211) -> 11013681 | D11: =C11-B11 -> -14702818 | E11: =IF(B11<>0,(C11-B11)/ABS(B11),0) -> -0.57172705
A12: Nº Contratos | B12: =COUNTIF(BD_LUCRO!B2:B211,2025) -> 124 | C12: =COUNTIF(BD_LUCRO!B2:B211,2026) -> 86 | D12: =C12-B12 -> -38 | E12: =IF(B12<>0,(C12-B12)/ABS(B12),0) -> -0.30645161
A13: Margem Bruta % | B13: =IF(B3<>0,(B3+B4+B5+B6)/B3,0) -> 0.26893078 | C13: =IF(C3<>0,(C3+C4+C5+C6)/C3,0) -> 0.76932868 | D13: =C13-B13 -> 0.5003979 | E13: =IF(B13<>0,(C13-B13)/ABS(B13),0) -> 1.8606941
A14: Margem Líquida % | B14: =IF(B3<>0,B9/B3,0) -> 0.07501755 | C14: =IF(C3<>0,C9/C3,0) -> 0.05114807 | D14: =C14-B14 -> -0.02386948 | E14: =IF(B14<>0,(C14-B14)/ABS(B14),0) -> -0.31818528
A16: EVOLUÇÃO MENSAL COMPARATIVA — Lucro Líquido Operacional
A17: Mês | B17: 2025 | C17: 2026 | D17: Δ R$ | E17: Δ %
A18: Janeiro | B18: =SUMPRODUCT((BD_LUCRO!B2:B211=2025)*(MONTH(BD_LUCRO!C2:C211)=1)*IF(ISNUMBER(BD_LUCRO!P2:P211),BD_LUCRO!P2:P211,0)) -> 106231.7 | C18: =SUMPRODUCT((BD_LUCRO!B2:B211=2026)*(MONTH(BD_LUCRO!C2:C211)=1)*IF(ISNUMBER(BD_LUCRO!P2:P211),BD_LUCRO!P2:P211,0)) -> 259819.54 | D18: =C18-B18 -> 153587.84 | E18: =IF(B18<>0,(C18-B18)/ABS(B18),0) -> 1.4457816
A19: Fevereiro | B19: =SUMPRODUCT((BD_LUCRO!B2:B211=2025)*(MONTH(BD_LUCRO!C2:C211)=2)*IF(ISNUMBER(BD_LUCRO!P2:P211),BD_LUCRO!P2:P211,0)) -> 716883.4 | C19: =SUMPRODUCT((BD_LUCRO!B2:B211=2026)*(MONTH(BD_LUCRO!C2:C211)=2)*IF(ISNUMBER(BD_LUCRO!P2:P211),BD_LUCRO!P2:P211,0)) -> 487694.56 | D19: =C19-B19 -> -229188.84 | E19: =IF(B19<>0,(C19-B19)/ABS(B19),0) -> -0.3197017
A20: Março | B20: =SUMPRODUCT((BD_LUCRO!B2:B211=2025)*(MONTH(BD_LUCRO!C2:C211)=3)*IF(ISNUMBER(BD_LUCRO!P2:P211),BD_LUCRO!P2:P211,0)) -> 1154496.8 | C20: =SUMPRODUCT((BD_LUCRO!B2:B211=2026)*(MONTH(BD_LUCRO!C2:C211)=3)*IF(ISNUMBER(BD_LUCRO!P2:P211),BD_LUCRO!P2:P211,0)) -> 561581.17 | D20: =C20-B20 -> -592915.67 | E20: =IF(B20<>0,(C20-B20)/ABS(B20),0) -> -0.51357063
A21: Abril | B21: =SUMPRODUCT((BD_LUCRO!B2:B211=2025)*(MONTH(BD_LUCRO!C2:C211)=4)*IF(ISNUMBER(BD_LUCRO!P2:P211),BD_LUCRO!P2:P211,0)) -> 499270.09 | C21: =SUMPRODUCT((BD_LUCRO!B2:B211=2026)*(MONTH(BD_LUCRO!C2:C211)=4)*IF(ISNUMBER(BD_LUCRO!P2:P211),BD_LUCRO!P2:P211,0)) -> 30408.19 | D21: =C21-B21 -> -468861.9 | E21: =IF(B21<>0,(C21-B21)/ABS(B21),0) -> -0.93909471
A22: Maio | B22: =SUMPRODUCT((BD_LUCRO!B2:B211=2025)*(MONTH(BD_LUCRO!C2:C211)=5)*IF(ISNUMBER(BD_LUCRO!P2:P211),BD_LUCRO!P2:P211,0)) -> 520095.42 | C22: =SUMPRODUCT((BD_LUCRO!B2:B211=2026)*(MONTH(BD_LUCRO!C2:C211)=5)*IF(ISNUMBER(BD_LUCRO!P2:P211),BD_LUCRO!P2:P211,0)) -> 88157.7 | D22: =C22-B22 -> -431937.72 | E22: =IF(B22<>0,(C22-B22)/ABS(B22),0) -> -0.83049707
A23: Junho | B23: =SUMPRODUCT((BD_LUCRO!B2:B211=2025)*(MONTH(BD_LUCRO!C2:C211)=6)*IF(ISNUMBER(BD_LUCRO!P2:P211),BD_LUCRO!P2:P211,0)) -> 60153.78 | C23: =SUMPRODUCT((BD_LUCRO!B2:B211=2026)*(MONTH(BD_LUCRO!C2:C211)=6)*IF(ISNUMBER(BD_LUCRO!P2:P211),BD_LUCRO!P2:P211,0)) -> 0 | D23: =C23-B23 -> -60153.78 | E23: =IF(B23<>0,(C23-B23)/ABS(B23),0) -> -1
A24: Julho | B24: =SUMPRODUCT((BD_LUCRO!B2:B211=2025)*(MONTH(BD_LUCRO!C2:C211)=7)*IF(ISNUMBER(BD_LUCRO!P2:P211),BD_LUCRO!P2:P211,0)) -> 93877.56 | C24: =SUMPRODUCT((BD_LUCRO!B2:B211=2026)*(MONTH(BD_LUCRO!C2:C211)=7)*IF(ISNUMBER(BD_LUCRO!P2:P211),BD_LUCRO!P2:P211,0)) -> 0 | D24: =C24-B24 -> -93877.56 | E24: =IF(B24<>0,(C24-B24)/ABS(B24),0) -> -1
A25: Agosto | B25: =SUMPRODUCT((BD_LUCRO!B2:B211=2025)*(MONTH(BD_LUCRO!C2:C211)=8)*IF(ISNUMBER(BD_LUCRO!P2:P211),BD_LUCRO!P2:P211,0)) -> 357771.6 | C25: =SUMPRODUCT((BD_LUCRO!B2:B211=2026)*(MONTH(BD_LUCRO!C2:C211)=8)*IF(ISNUMBER(BD_LUCRO!P2:P211),BD_LUCRO!P2:P211,0)) -> 0 | D25: =C25-B25 -> -357771.6 | E25: =IF(B25<>0,(C25-B25)/ABS(B25),0) -> -1
A26: Setembro | B26: =SUMPRODUCT((BD_LUCRO!B2:B211=2025)*(MONTH(BD_LUCRO!C2:C211)=9)*IF(ISNUMBER(BD_LUCRO!P2:P211),BD_LUCRO!P2:P211,0)) -> 207587.74 | C26: =SUMPRODUCT((BD_LUCRO!B2:B211=2026)*(MONTH(BD_LUCRO!C2:C211)=9)*IF(ISNUMBER(BD_LUCRO!P2:P211),BD_LUCRO!P2:P211,0)) -> 0 | D26: =C26-B26 -> -207587.74 | E26: =IF(B26<>0,(C26-B26)/ABS(B26),0) -> -1
A27: Outubro | B27: =SUMPRODUCT((BD_LUCRO!B2:B211=2025)*(MONTH(BD_LUCRO!C2:C211)=10)*IF(ISNUMBER(BD_LUCRO!P2:P211),BD_LUCRO!P2:P211,0)) -> 233803.58 | C27: =SUMPRODUCT((BD_LUCRO!B2:B211=2026)*(MONTH(BD_LUCRO!C2:C211)=10)*IF(ISNUMBER(BD_LUCRO!P2:P211),BD_LUCRO!P2:P211,0)) -> 0 | D27: =C27-B27 -> -233803.58 | E27: =IF(B27<>0,(C27-B27)/ABS(B27),0) -> -1
A28: Novembro | B28: =SUMPRODUCT((BD_LUCRO!B2:B211=2025)*(MONTH(BD_LUCRO!C2:C211)=11)*IF(ISNUMBER(BD_LUCRO!P2:P211),BD_LUCRO!P2:P211,0)) -> 165851.95 | C28: =SUMPRODUCT((BD_LUCRO!B2:B211=2026)*(MONTH(BD_LUCRO!C2:C211)=11)*IF(ISNUMBER(BD_LUCRO!P2:P211),BD_LUCRO!P2:P211,0)) -> 0 | D28: =C28-B28 -> -165851.95 | E28: =IF(B28<>0,(C28-B28)/ABS(B28),0) -> -1
A29: Dezembro | B29: =SUMPRODUCT((BD_LUCRO!B2:B211=2025)*(MONTH(BD_LUCRO!C2:C211)=12)*IF(ISNUMBER(BD_LUCRO!P2:P211),BD_LUCRO!P2:P211,0)) -> 84051.78 | C29: =SUMPRODUCT((BD_LUCRO!B2:B211=2026)*(MONTH(BD_LUCRO!C2:C211)=12)*IF(ISNUMBER(BD_LUCRO!P2:P211),BD_LUCRO!P2:P211,0)) -> 0 | D29: =C29-B29 -> -84051.78 | E29: =IF(B29<>0,(C29-B29)/ABS(B29),0) -> -1
A30: TOTAL ANUAL | B30: =SUM(B18:B29) -> 4200075.4 | C30: =SUM(C18:C29) -> 1427661.2 | D30: =SUM(D18:D29) -> -2772414.3 | E30: =IF(B30<>0,(C30-B30)/ABS(B30),0) -> -0.66008678

Sheet BD_LUCRO
A1: Empresa | B1: Ano | C1: Mês | D1: Contrato V | E1: Contrato C | F1: Fornecedor | G1: Cliente | H1: Produto | I1: Peso Kg | J1: Sacas/Ton | K1: Lucro Bruto | L1: Total Frete | M1: Impostos | N1: Comissão | O1: Outros | P1: Lucro Líq. | Q1: Lucro Sc/Tn
A2: MM | B2: 2025 | C2: 45658 | D2: 0194/25 - SO | E2: 0195/25 - SO | F2: ANACLETO BRUNETTA E OUTROS | G2: ENGELHART CTP BRASIL S.A. | H2: SOJA EM GRAOS | I2: 558840 | J2: =I2/60 -> 9314 | K2: 138070 | L2: 94425.6 | M2: 0 | N2: 5658.25 | O2: 0 | P2: 37986.15 | Q2: =BD_LUCRO[[#This Row],[Lucro Líq.]]/BD_LUCRO[[#This Row],[Sacas/Ton]] -> 4.0783927
A3: MM | B3: 2025 | C3: 45658 | D3: 0198/25 - SO | E3: 0197/25 - SO | F3: IVETE TEREZINHA GALLO | G3: LOUIS DREYFUS COMPANY BRASIL S.A. | H3: SOJA EM GRAOS | I3: 413950 | J3: =I3/60 -> 6899.1667 | K3: 34495.83 | L3: 0 | M3: 0 | N3: 2069.75 | O3: 0 | P3: 32426.08 | Q3: =BD_LUCRO[[#This Row],[Lucro Líq.]]/BD_LUCRO[[#This Row],[Sacas/Ton]] -> 4.6999995
A4: MM | B4: 2025 | C4: 45658 | D4: 0199/25 - SO | E4: 0195/25 - SO | F4: ANACLETO BRUNETTA E OUTROS | G4: ENGELHART CTP (BRASIL) S.A. | H4: SOJA EM GRAOS | I4: 309400 | J4: =I4/60 -> 5156.6667 | K4: 110649.6 | L4: 81294.4 | M4: 0 | N4: 3145.57 | O4: 0 | P4: 23867.52 | Q4: =BD_LUCRO[[#This Row],[Lucro Líq.]]/BD_LUCRO[[#This Row],[Sacas/Ton]] -> 4.6284783
A5: MM | B5: 2025 | C5: 45689 | D5: - | E5: 0204/25 - POP | F5: SOMAR AGRONEGOCIOS EIRELLI ME | G5: - | H5: POP QUIMAR 164 | I5: 40 | J5: =I5/60 -> 0.66666667 | K5: 0 | L5: 0 | M5: 0 | N5: 0 | O5: 0 | P5: 0 | Q5: =BD_LUCRO[[#This Row],[Lucro Líq.]]/BD_LUCRO[[#This Row],[Sacas/Ton]] -> 0
A6: MM | B6: 2025 | C6: 45689 | D6: 0188/24 - SO | E6: 0179/24 - SO | F6: RICARDO PANCOTTE | G6: BUNGE ALIMENTOS S/A | H6: SOJA EM GRAOS | I6: 134954 | J6: =I6/60 -> 2249.2333 | K6: 61086.48 | L6: 0 | M6: 0 | N6: 1124.62 | O6: 0 | P6: 59961.86 | Q6: =BD_LUCRO[[#This Row],[Lucro Líq.]]/BD_LUCRO[[#This Row],[Sacas/Ton]] -> 26.658799
A7: MM | B7: 2025 | C7: 45689 | D7: 0191/25 - SO | E7: 0179/24 - SO | F7: RICARDO PANCOTTE | G7: LOUIS DREYFUS COMPANY BRASIL S.A. | H7: SOJA EM GRAOS | I7: 222150 | J7: =I7/60 -> 3702.5 | K7: 106439.1 | L7: 0 | M7: 0 | N7: 1851.25 | O7: 0 | P7: 104587.85 | Q7: =BD_LUCRO[[#This Row],[Lucro Líq.]]/BD_LUCRO[[#This Row],[Sacas/Ton]] -> 28.2479
A8: MM | B8: 2025 | C8: 45689 | D8: 0192/25 - SO | E8: 0177/24 - SO | F8: SILVIO CESAR VERDELIO E OUTRO | G8: AMAGGI EXPORTACAO E IMPORTACAO LTDA | H8: SOJA EM GRAOS | I8: 498138 | J8: =I8/60 -> 8302.3 | K8: 263630.4 | L8: 0 | M8: 0 | N8: 4151.15 | O8: 0 | P8: 259479.25 | Q8: =BD_LUCRO[[#This Row],[Lucro Líq.]]/BD_LUCRO[[#This Row],[Sacas/Ton]] -> 31.2539
A9: MM | B9: 2025 | C9: 45689 | D9: 0196/25 - SO | E9: 0200/25 - SO | F9: FERNANDO CESAR FACHOLLI | G9: LOUIS DREYFUS COMPANY BRASIL S.A. | H9: SOJA EM GRAOS | I9: 98041 | J9: =I9/60 -> 1634.0167 | K9: 31373.12 | L9: 0 | M9: 0 | N9: 490.21 | O9: 0 | P9: 30882.92 | Q9: =BD_LUCRO[[#This Row],[Lucro Líq.]]/BD_LUCRO[[#This Row],[Sacas/Ton]] -> 18.900003
A10: MM | B10: 2025 | C10: 45689 | D10: 0196/25 - SO | E10: 0201/25 - SO | F10: IVETE TEREZINHA GALLO | G10: LOUIS DREYFUS COMPANY BRASIL S.A. | H10: SOJA EM GRAOS | I10: 33405 | J10: =I10/60 -> 556.75 | K10: 4175.63 | L10: 0 | M10: 0 | N10: 167.03 | O10: 0 | P10: 4008.6 | Q10: =BD_LUCRO[[#This Row],[Lucro Líq.]]/BD_LUCRO[[#This Row],[Sacas/Ton]] -> 7.2
A11: MM | B11: 2025 | C11: 45689 | D11: 0196/25 - SO | E11: 0179/24 - SO | F11: RICARDO PANCOTTE | G11: LOUIS DREYFUS COMPANY BRASIL S.A. | H11: SOJA EM GRAOS | I11: 418009 | J11: =I11/60 -> 6966.8167 | K11: 217698.39 | L11: 0 | M11: 0 | N11: 3483.41 | O11: 0 | P11: 214214.98 | Q11: =BD_LUCRO[[#This Row],[Lucro Líq.]]/BD_LUCRO[[#This Row],[Sacas/Ton]] -> 30.7479
A12: MM | B12: 2025 | C12: 45689 | D12: 0196/25 - SO | E12: 0177/24 - SO | F12: SILVIO CESAR VERDELIO E OUTRO | G12: LOUIS DREYFUS COMPANY BRASIL S.A. | H12: SOJA EM GRAOS | I12: 50545 | J12: =I12/60 -> 842.41667 | K12: 28856.06 | L12: 0 | M12: 0 | N12: 252.73 | O12: 0 | P12: 28603.33 | Q12: =BD_LUCRO[[#This Row],[Lucro Líq.]]/BD_LUCRO[[#This Row],[Sacas/Ton]] -> 33.953899
A13: MM | B13: 2025 | C13: 45689 | D13: 0198/25 - SO | E13: 0197/25 - SO | F13: IVETE TEREZINHA GALLO | G13: LOUIS DREYFUS COMPANY BRASIL S.A. | H13: SOJA EM GRAOS | I13: 186050 | J13: =I13/60 -> 3100.8333 | K13: 15504.17 | L13: 0 | M13: 0 | N13: 930.25 | O13: 0 | P13: 14573.92 | Q13: =BD_LUCRO[[#This Row],[Lucro Líq.]]/BD_LUCRO[[#This Row],[Sacas/Ton]] -> 4.7000011
... A211: BC_MATRIZ | B211: 2026 | C211: 46143 | D211: 0483/26 - SO | E211: 0482/26 - SO | F211: ANDREY GUSTAVO GALLO | G211: AMAGGI EXPORTACAO E IMPORTACAO LTDA | H211: SOJA EM GRAOS | I211: 1959060 | J211: =I211/60 -> 32651 | K211: 111013.4 | L211: 0 | M211: 0 | N211: 22855.7 | O211: 0 | P211: 88157.7 | Q211: =BD_LUCRO[[#This Row],[Lucro Líq.]]/BD_LUCRO[[#This Row],[Sacas/Ton]] -> 2.7
A212: Total | I212: =SUBTOTAL(109,BD_LUCRO[Peso Kg]) -> 36730180 | J212: =SUBTOTAL(109,BD_LUCRO[Sacas/Ton]) -> 612169.67 | K212: =SUBTOTAL(109,BD_LUCRO[Lucro Bruto]) -> 8797015.3 | L212: =SUBTOTAL(109,BD_LUCRO[Total Frete]) -> 3422858.8 | M212: =SUBTOTAL(109,BD_LUCRO[Impostos]) -> 73243.42 | N212: =SUBTOTAL(109,BD_LUCRO[Comissão]) -> 2018865 | O212: =SUBTOTAL(109,BD_LUCRO[Outros]) -> 5650.4 | P212: =SUBTOTAL(109,BD_LUCRO[Lucro Líq.]) -> 5627736.6 | Q212: =SUBTOTAL(109,BD_LUCRO[Lucro Sc/Tn]) -> 43.560205

Sheet BD_DESP
A1: Empresa | B1: Ano | C1: Mês | D1: Item | E1: Valor
A2: MM | B2: 2025 | C2: 45658 | D2: CSLL | E2: 26408.69
A3: MM | B3: 2025 | C3: 45658 | D3: CUSTAS CARTORIAIS | E3: 118.5
A4: MM | B4: 2025 | C4: 45658 | D4: ENERGIA | E4: 890.23
A5: MM | B5: 2025 | C5: 45658 | D5: HONORARIO CONTABEL | E5: 1518
A6: MM | B6: 2025 | C6: 45658 | D6: INFORMATICA | E6: 84
A7: MM | B7: 2025 | C7: 45658 | D7: INSS | E7: 813.97
A8: MM | B8: 2025 | C8: 45658 | D8: INTERNET | E8: 179.9
A9: MM | B9: 2025 | C9: 45658 | D9: IOF | E9: 191.89
A10: MM | B10: 2025 | C10: 45658 | D10: IRPF | E10: 52501.37
A11: MM | B11: 2025 | C11: 45658 | D11: IRPJ | E11: 2887.53
A12: MM | B12: 2025 | C12: 45658 | D12: JUROS EMPRESTIMOS | E12: 10422.03
A13: MM | B13: 2025 | C13: 45658 | D13: OUTROS IMPOSTOS E TAXAS | E13: 112
... A759: MM | B759: 2026 | C759: 46143 | D759: TARIFA BANCARIA | E759: 310.9
A760: Total | E760: =SUBTOTAL(109,BD_DESP[Valor]) -> 5011512.6

Sheet BD_REC_FIN
A1: Empresa | B1: DataPagto | C1: Descricao | D1: NomeClienteOk | E1: NDocumento | F1: DescricaoPlanoContas | G1: Parcela | H1: DescricaoFormaPagto | I1: ValorPagoR
A2: BC_FILIAL | B2: 45740 | C2: MERCADORIA REF 1225, CARREGAMENTO Nº 01627, CONTRATO: 0347/24 - AR. REVERTIDO LUCRO. | D2: J C M BEZERRA LTDA | E2: 03/2025 | F2: ENTRADAS DIVERSAS | G2: ÚNICA | H2: DEBITO EM CONTA | I2: 7896.01
A3: BC_FILIAL | B3: 45912 | C3: CREDITO PARA AJUSTAR BAIXA COMISSAO WARLEY OC 1994 CONTRATO CEL 0358/25 - FC. | D3: GLOBO COMERCIO DE CEREAIS LTDA | F3: TRANSFERENCIA ENTRE CONTAS | G3: ÚNICA | H3: TRANSFERENCIA | I3: 759.5
A4: BC_FILIAL | B4: 45930 | C4: AJUSTE CONTRATO 0002/24 - AZ. | D4: BANCO DO BRASIL SA | E4: 0002/24 - AZ | F4: ENTRADAS DIVERSAS | G4: ÚNICA | H4: TRANSFERENCIA | I4: 23507.68
A5: BC_FILIAL | B5: 45961 | C5: REVERSAO LUCRO DESPESAS OC 02076. | D5: JOEL FLORENCO DE SOUZA | E5: 02076 | F5: ENTRADAS DIVERSAS | G5: ÚNICA | H5: DINHEIRO | I5: 1841.67
A6: BC_FILIAL | B6: 46038 | C6: COMPRA PARCELA Nº 01 Ref Documento nº 6. MOVEIS SALA 505 SUL. | D6: MOVEMAR MOVEIS PERSONALIZADOS LTDA | E6: 6 | F6: ADIANTAMENTOS FORNECEDORES | G6: ÚNICA | H6: PIX | I6: 20000
A7: BC_FILIAL | B7: 46058 | C7: ADIANTAMENTO DO CONTRATO 0364/26 - MP. NF 123. | D7: SAMBA FOODS LTDA | E7: 0364/26 - MP | F7: CLIENTES MERCADORIAS | G7: ÚNICA | H7: PIX | I7: 187500
A8: BC_FILIAL | B8: 46062 | C8: ADIANTAMENTO DE CONTRATO VENDA 0365/26 - MP. NF 122. | D8: SAMBA FOODS LTDA | E8: 0365/26 - MP | F8: CLIENTES MERCADORIAS | G8: ÚNICA | H8: PIX | I8: 54250
A9: BC_FILIAL | B9: 46071 | C9: NF 202600000000001. PRESTACAO DE SERVICO DE ARMAZENAMENTO DE GRAOS EM CAMARA FRIA. MUNGO PRETO 9.300 KG. | D9: PORTO CEREAIS LTDA | E9: NF 202600000000001 | F9: ADIANTAMENTOS FORNECEDORES | G9: ÚNICA | H9: TRANSFERENCIA | I9: 6200
A10: BC_FILIAL | B10: 46079 | C10: MERCADORIA REF NF 122, CARREGAMENTO Nº 02288, CONTRATO: 0365/26 - MP. PLACA: XXX-9999, MOTORISTA: JOEL FLORENCO DE SOUZA | D10: SAMBA FOODS LTDA | E10: 02288 | F10: CLIENTES MERCADORIAS | G10: ÚNICA | H10: TRANSFERENCIA | I10: 4250
A11: BC_FILIAL | B11: 46080 | C11: COMPRA PARCELA Nº 01 Ref Documento nº 8 | D11: MOVEMAR MOVEIS PERSONALIZADOS LTDA | E11: 8 | F11: ADIANTAMENTOS FORNECEDORES | G11: ÚNICA | H11: PIX | I11: 678
A12: BC_MATRIZ | B12: 45659 | C12: ADIANTAMENTO CLIENTE (VENDA CAMINHAO). | D12: D.A. MANFROI TRANSPORTES LTDA | E12: 01/2025 | F12: ADIANTAMENTOS CLIENTES | G12: ÚNICA | H12: PIX | I12: 14647.19
A13: BC_MATRIZ | B13: 45659 | C13: RESGATE | D13: TRANSFERENCIA ENTRE CONTAS | E13: 01/2025 | F13: TRANSFERENCIA ENTRE CONTAS | G13: ÚNICA | H13: TRANSFERENCIA | I13: 853.8
A14: BC_MATRIZ | B14: 45663 | C14: RESGATE | D14: TRANSFERENCIA ENTRE CONTAS | E14: 01/2025 | F14: TRANSFERENCIA ENTRE CONTAS | G14: ÚNICA | H14: TRANSFERENCIA | I14: 188.78
A15: BC_MATRIZ | B15: 45664 | C15: RESGATE | D15: TRANSFERENCIA ENTRE CONTAS | E15: 01/2025 | F15: TRANSFERENCIA ENTRE CONTAS | G15: ÚNICA | H15: TRANSFERENCIA | I15: 7118.89
... A1669: MM | B1669: 46171 | C1669: RENDIMENTO APLICACAO | D1669: BANCO DO BRASIL SA | E1669: 05/2026 | F1669: RENDIMETO FINANCEIRO | G1669: ÚNICA | H1669: CREDITO EM CONTA | I1669: 2307.11
A1670: Total | I1670: =SUBTOTAL(109,BD_REC_FIN[ValorPagoR]) -> 2.1426446e+08

Sheet BD_DESP_COMPL
A1: Empresa | B1: DataPagto | C1: Descricao | D1: NomeCC | E1: NomeClienteOk | F1: NDocumento | G1: DescricaoPlanoContas | H1: Parcela | I1: DescricaoFormaPagto | J1: ValorPagoR
A2: BC_FILIAL | B2: 45716 | C2: MERCADORIA REF 1225, CARREGAMENTO Nº 01627, CONTRATO: 0347/24 - AR. PLACA: AEN-4B16, MOTORISTA: ALIPIO NEVES DE ANDRADE. EXTRATO Porto Cereais Agroindustri | D2: BELA CEREAIS COMERCIO | E2: J C M BEZERRA LTDA | F2: 01627 | G2: FORNECEDORES MERCADORIA | H2: ÚNICA | I2: DINHEIRO | J2: 9999.99
A3: BC_FILIAL | B3: 45716 | C3: MERCADORIA REF 1225, CARREGAMENTO Nº 01627, CONTRATO: 0347/24 - AR. PLACA: AEN-4B16, MOTORISTA: ALIPIO NEVES DE ANDRADE. EXTRATO Porto Cereais Agroindustri | D3: BELA CEREAIS COMERCIO | E3: J C M BEZERRA LTDA | F3: 01627 | G3: FORNECEDORES MERCADORIA | H3: ÚNICA | I3: DINHEIRO | J3: 3000
A4: BC_FILIAL | B4: 45721 | C4: MERCADORIA REF 1225, CARREGAMENTO Nº 01627, CONTRATO: 0347/24 - AR. PLACA: AEN-4B16, MOTORISTA: ALIPIO NEVES DE ANDRADE. EXTRATO Porto Cereais Agroindustri | D4: BELA CEREAIS COMERCIO | E4: J C M BEZERRA LTDA | F4: 01627 | G4: FORNECEDORES MERCADORIA | H4: ÚNICA | I4: DINHEIRO | J4: 2360
A5: BC_FILIAL | B5: 45740 | C5: CTE 21419. CHAPA DESCARGA CONFRESA | D5: BELA CEREAIS COMERCIO | E5: JOEL FLORENCO DE SOUZA | F5: 01628 | G5: OUTRAS DESPESAS (CORRETORA) | H5: ÚNICA | I5: TRANSFERENCIA | J5: 475
A6: BC_FILIAL | B6: 45740 | C6: CTE 21419. CHAPA DESCARGA CONFRESA | D6: BELA CEREAIS COMERCIO | E6: JOEL FLORENCO DE SOUZA | F6: 01628 | G6: PRO-LABORE | H6: ÚNICA | I6: TRANSFERENCIA | J6: 4.1
A7: BC_FILIAL | B7: 45740 | C7: MERCADORIA REF 1225, CARREGAMENTO Nº 01627, CONTRATO: 0347/24 - AR. PLACA: AEN-4B16, MOTORISTA: ALIPIO NEVES DE ANDRADE. EXTRATO Porto Cereais Agroindustri | D7: BELA CEREAIS COMERCIO | E7: J C M BEZERRA LTDA | F7: 01627 | G7: FORNECEDORES MERCADORIA | H7: ÚNICA | I7: DINHEIRO | J7: 7896.01
A8: BC_FILIAL | B8: 45790 | C8: RESGATE | D8: BELA CEREAIS COMERCIO | E8: TRANSFERENCIA ENTRE CONTAS | F8: 05/2025 | G8: TRANSFERENCIA ENTRE CONTAS | H8: ÚNICA | I8: TRANSFERENCIA | J8: 972.4
A9: BC_FILIAL | B9: 45791 | C9: MERCADORIA REF NF 139 E 140, CARREGAMENTO Nº 01940 E 01941, CONTRATO: 0355/25 - MV. PLACA: XXX-9999, MOTORISTA: JOEL FLORENCO DE SOUZA. FATURA Nº 00791 REF. DOCUMENTOS: 01940, 01941. CESSAO DE CREDITO DE CAMPO VERDE AGRONEGOCIO PARA PAGAMENTO ADEMAR VANZ | D9: BELA CEREAIS COMERCIO | E9: ADEMAR VANZELA | F9: 01940 | G9: FORNECEDORES MERCADORIA | H9: ÚNICA | I9: TRANSFERENCIA | J9: 152538.6
A10: BC_FILIAL | B10: 45791 | C10: MERCADORIA, CARREGAMENTO Nº 01940 E 01941, CONTRATO: 0355/25 - MV. PLACA: XXX-9999, MOTORISTA: JOEL FLORENCO DE SOUZA. FATURA Nº 00791 REF. DOCUMENTOS: 01940, 01941. CESSAO DE CREDITO DE GRUPO ENZO PARA PAGAMENTO ADEMAR VANZELA. | D10: BELA CEREAIS COMERCIO | E10: ADEMAR VANZELA | F10: 01940 | G10: FORNECEDORES MERCADORIA | H10: ÚNICA | I10: TRANSFERENCIA | J10: 57725.03
A11: BC_FILIAL | B11: 45796 | C11: COMPRA PARCELA Nº 01 Ref Documento nº 189497 | D11: BELA CEREAIS COMERCIO | E11: Rafitec S/A Ind. e Com. De Sacarias | F11: 189497 | G11: DIVERSOS | H11: 1/1 | I11: TRANSFERENCIA | J11: 31827.5
A12: BC_FILIAL | B12: 45798 | C12: SALDO FRETE Nº 01940, CTE 3524 PARCIAL GRUPO ENZO, CONTRATO: . PLACA: XXX-9999, MOTORISTA: JOEL FLORENCO DE SOUZA. EXTRATO KPA DEISEL. | D12: BELA CEREAIS COMERCIO | E12: JOEL FLORENCO DE SOUZA | F12: 01940 | G12: FRETE (ADTO/SALDO) | H12: ÚNICA | I12: PIX | J12: 9822
A13: BC_FILIAL | B13: 45798 | C13: SALDO FRETE Nº 01941, CTE 32122 NEROWILLIAN, CONTRATO: . PLACA: XXX-9999, MOTORISTA: JOEL FLORENCO DE SOUZA | D13: BELA CEREAIS COMERCIO | E13: JOEL FLORENCO DE SOUZA | F13: 01941 | G13: FRETE (ADTO/SALDO) | H13: ÚNICA | I13: PIX | J13: 7614
... A163: BC_MATRIZ | B163: 45685 | C163: PAGAMENTO ANTECIPADO CONTRATO CONTRA E VANDA 042/2025 (BELA X MM). | D163: BELA CEREAIS COMERCIO | E163: MM COMERCIO DE CEREAIS LTDA | F163: 042/2025 | G163: EMPRESAS | H163: ÚNICA | I163: TRANSFERENCIA | J163: 1000000
A164: BC_MATRIZ | B164: 45686 | C164: REGISTRO DOMINIO MARCA MM. | D164: BELA CEREAIS COMERCIO | E164: NUCLEO DE INFORMACAO E COORDENACAO DO PONTO BR - NIC .BR | G164: HONORARIOS DIVERSOS | H164: ÚNICA | I164: BOLETO | J164: 364
A165: BC_MATRIZ | B165: 45686 | C165: RESGATE | D165: BELA CEREAIS COMERCIO | E165: TRANSFERENCIA ENTRE CONTAS | F165: 01/2025 | G165: TRANSFERENCIA ENTRE CONTAS | H165: ÚNICA | I165: TRANSFERENCIA | J165: 364
A166: BC_MATRIZ | B166: 45687 | C166: IRPJ 4º TRIMESTRE 2024. | D166: BELA CEREAIS COMERCIO | E166: MINISTERIO DA FAZENDA | F166: 12/2024 | G166: IRPF | H166: ÚNICA | I166: BOLETO | J166: 24.55
A167: BC_MATRIZ | B167: 45687 | C167: PRO LABORE. | D167: BELA CEREAIS COMERCIO | E167: JOEL FLORENCO DE SOUZA | F167: 01/2025 | G167: PRO-LABORE | H167: 1/12 | I167: TRANSFERENCIA | J167: 2314
A168: BC_MATRIZ | B168: 45687 | C168: PAGAMENTO ANTECIPADO CONTRATO CONTRA E VANDA 042/2025 (BELA X MM). | D168: BELA CEREAIS COMERCIO | E168: MM COMERCIO DE CEREAIS LTDA | F168: 042/2025 | G168: EMPRESAS | H168: ÚNICA | I168: TRANSFERENCIA | J168: 300000
A169: BC_MATRIZ | B169: 45687 | C169: RESGATE | D169: BELA CEREAIS COMERCIO | E169: TRANSFERENCIA ENTRE CONTAS | F169: 01/2025 | G169: TRANSFERENCIA ENTRE CONTAS | H169: ÚNICA | I169: TRANSFERENCIA | J169: 302338.55
A170: BC_MATRIZ | B170: 45688 | C170: ARRECADAÇÃO MUNICIPAL TAXA LICENCA FUNCIONAMENTO 2025. | D170: BELA CEREAIS COMERCIO | E170: PREFEITURA DE CUIABA | F170: 01/2025 | G170: OUTROS IMPOSTOS E TAXAS | H170: ÚNICA | I170: BOLETO | J170: 273.29
A171: BC_MATRIZ | B171: 45688 | C171: SALDO FRETE Nº 01636, CTE 17359, CONTRATO: 0354/25 - ML. PLACA: FIV-1F92, MOTORISTA: EDER EDUARDO BARBOSA. EXTRATO FEROLI TRANSPORTES. | D171: BELA CEREAIS COMERCIO | E171: EDER EDUARDO BARBOSA | F171: 01636 | G171: FRETE (ADTO/SALDO) | H171: ÚNICA | I171: PIX | J171: 14002.46
A172: BC_MATRIZ | B172: 45688 | C172: SALDO FRETE Nº 01638, CTE 17366, CONTRATO: 0354/25 - ML. PLACA: XXX-9999, MOTORISTA: JOEL FLORENCO DE SOUZA. EXTRATO FEROLI TRANSPORTES. | D172: BELA CEREAIS COMERCIO | E172: JOEL FLORENCO DE SOUZA | F172: 01638 | G172: FRETE (ADTO/SALDO) | H172: ÚNICA | I172: PIX | J172: 9958
A173: BC_MATRIZ | B173: 45688 | C173: SALDO FRETE Nº 01637, CTE 17363, CONTRATO: 0354/25 - ML. PLACA: XXX-9999, MOTORISTA: JOEL FLORENCO DE SOUZA. FATURA Nº 00760 REF. DOCUMENTOS: 01637, 01637. EXTRATO FEROLI TRANSPORTES. | D173: BELA CEREAIS COMERCIO | E173: JOEL FLORENCO DE SOUZA | F173: 01637 | G173: FRETE (ADTO/SALDO) | H173: ÚNICA | I173: PIX | J173: 11888.4
A174: BC_MATRIZ | B174: 45688 | C174: SALDO FRETE Nº 01636, CTE 26868 PARCIAL, CONTRATO: 0354/25 - ML. PLACA: FIV-1F92, MOTORISTA: EDER EDUARDO BARBOSA. EXTRATO FEROLI TRANSPORTES. | D174: BELA CEREAIS COMERCIO | E174: EDER EDUARDO BARBOSA | F174: 01636 | G174: FRETE (ADTO/SALDO) | H174: ÚNICA | I174: PIX | J174: 1615.42
A175: BC_MATRIZ | B175: 45688 | C175: SALDO FRETE Nº 01638, CTE 17363, CONTRATO: 0354/25 - ML. PLACA: XXX-9999, MOTORISTA: JOEL FLORENCO DE SOUZA. EXTRATO FEROLI TRANSPORTES. | D175: BELA CEREAIS COMERCIO | E175: JOEL FLORENCO DE SOUZA | F175: 01638 | G175: FRETE (ADTO/SALDO) | H175: ÚNICA | I175: PIX | J175: 498
A176: BC_MATRIZ | B176: 45688 | C176: SALDO FRETE Nº 01638, CTE 32200 PARCIAL, CONTRATO: 0354/25 - ML. PLACA: XXX-9999, MOTORISTA: JOEL FLORENCO DE SOUZA. EXTRATO FEROLI TRANSPORTES. | D176: BELA CEREAIS COMERCIO | E176: JOEL FLORENCO DE SOUZA | F176: 01638 | G176: FRETE (ADTO/SALDO) | H176: ÚNICA | I176: PIX | J176: 729.98
... A2936: MM | B2936: 45812 | C2936: RESTAGE | D2936: MM COMERCIO DE CEREAIS | E2936: TRANSFERENCIA ENTRE CONTAS | F2936: 06/2025 | G2936: TRANSFERENCIA ENTRE CONTAS | H2936: ÚNICA | I2936: TRANSFERENCIA | J2936: 7567
A2937: MM | B2937: 45813 | C2937: PAGAMENTO JUROS REFERENTE AO CONTRATO DE MUTUO ENTRE SOCIO E EMPRESA DATADO DE 01/05/2025. | D2937: MM COMERCIO DE CEREAIS | E2937: MARCIA MORATELLI | F2937: 05/2025 | G2937: JUROS S/ MUTUO SOCIO | I2937: TRANSFERENCIA | J2937: 3303.92
A2938: MM | B2938: 45813 | C2938: CTE 32567 R$ 2212,69 PARCIAL. CTE 32568 R$ 787,31 PARCIAL. | D2938: MM COMERCIO DE CEREAIS | E2938: NEROWILLIAN DIAS DE SOUZA TRANSPORTES | F2938: 06/2025 | G2938: PRO-LABORE | H2938: ÚNICA | I2938: DINHEIRO | J2938: 3000
A2939: MM | B2939: 45813 | C2939: PARCELA PRIMEIRA (1/03) REFERENTE AO IMOVEL ADIQUIDO EM CONFRESA ÁREA: 6,1364ha. CONFORME INSTRUMENTO PARTICULAR DE COMPROMISSO DE VENDA E COMPRA DE IMÓVEL RURAL, NA FORMA ABAIXO DATADO 02/06/2025. | D2939: MM COMERCIO DE CEREAIS | E2939: AFONSO DE OLIVEIRA CARVALHO | F2939: 06/2025 | G2939: IMOVEIS | H2939: 1/3 | I2939: TED | J2939: 150000
A2940: MM | B2940: 45813 | C2940: SALDO FRETE Nº 01955, CTE 38638 NEROWILLIAN, CONTRATO: . PLACA: OCM-0I34, MOTORISTA: FRANCISCO MARTINS SANTANA | D2940: MM COMERCIO DE CEREAIS | E2940: FRANCISCO MARTINS SANTANA | F2940: 01955 | G2940: FRETE (ADTO/SALDO) | H2940: ÚNICA | I2940: PIX | J2940: 6404.8
A2941: MM | B2941: 45813 | C2941: TARIFA | D2941: MM COMERCIO DE CEREAIS | E2941: BANCO DO BRASIL SA | F2941: 06/2025 | G2941: TARIFA BANCARIA | H2941: ÚNICA | I2941: DEBITO EM CONTA | J2941: 10
A2942: MM | B2942: 45813 | C2942: RESGATE | D2942: MM COMERCIO DE CEREAIS | E2942: TRANSFERENCIA ENTRE CONTAS | F2942: 06/2025 | G2942: TRANSFERENCIA ENTRE CONTAS | H2942: ÚNICA | I2942: TRANSFERENCIA | J2942: 9565
A2943: MM | B2943: 45813 | C2943: RESGATE | D2943: MM COMERCIO DE CEREAIS | E2943: TRANSFERENCIA ENTRE CONTAS | F2943: 06/2025 | G2943: TRANSFERENCIA ENTRE CONTAS | H2943: ÚNICA | I2943: TRANSFERENCIA | J2943: 16185.55
A2944: MM | B2944: 45813 | C2944: SALDO FRETE Nº 01955, CTE 32568 NEROWILLIAN, CONTRATO: . PLACA: OCM-0I34, MOTORISTA: FRANCISCO MARTINS SANTANA | D2944: MM COMERCIO DE CEREAIS | E2944: FRANCISCO MARTINS SANTANA | F2944: 01955 | G2944: FRETE (ADTO/SALDO) | H2944: ÚNICA | I2944: PIX | J2944: 2594.4
A2945: MM | B2945: 45813 | C2945: RESGATE | D2945: MM COMERCIO DE CEREAIS | E2945: TRANSFERENCIA ENTRE CONTAS | F2945: 06/2025 | G2945: TRANSFERENCIA ENTRE CONTAS | H2945: ÚNICA | I2945: TRANSFERENCIA | J2945: 162888.62
A2946: MM | B2946: 45813 | C2946: INTERNET 05/2025. | D2946: MM COMERCIO DE CEREAIS | E2946: ABS TELECOMUNICACOES LTDA | F2946: 05/2025 | G2946: INTERNET | H2946: 5/12 | I2946: BOLETO | J2946: 179.9
A2947: MM | B2947: 45814 | C2947: IAGRO CONTRATO: 0215/25 - SO 531,81 TONS, CARREGAMENTO Nº 01909, CONTRATO: 0215/25 - SO. PLACA: XXX-9999, MOTORISTA: JOEL FLORENCO DE SOUZA | D2947: MM COMERCIO DE CEREAIS | E2947: SANTA RITA AGRONEGOCIOS LTDA | F2947: 0215/25 - SO | G2947: FETHAB | H2947: ÚNICA | I2947: BOLETO | J2947: 1489.14
A2948: MM | B2948: 45814 | C2948: FETHAB REF NF 7810, CARREGAMENTO Nº 01938, CONTRATO: 0195/25 - SO. PLACA: XXX-9999, MOTORISTA: JOEL FLORENCO DE SOUZA | D2948: MM COMERCIO DE CEREAIS | E2948: ANACLETO BRUNETTA E OUTROS | F2948: 01938 | G2948: FETHAB | H2948: ÚNICA | I2948: BOLETO | J2948: 1033.86
...

Sheet HIST. MENSAL
B2: GRUPO | E2: BELA CEREAIS | H2: MM
B3: Resumo Global | E3: Resumo Global | H3: Resumo Global
B4: Lucro Bruto (Contratos) | C4: =BD_LUCRO[[#Totals],[Lucro Bruto]] -> 8797015.3 | E4: Lucro Bruto (Contratos) | H4: Lucro Bruto (Contratos)
B5: (-) Total Frete | C5: =-BD_LUCRO[[#Totals],[Total Frete]] -> -3422858.8 | E5: (-) Total Frete | H5: (-) Total Frete
B6: (-) Impostos Contratos | C6: =-BD_LUCRO[[#Totals],[Impostos]] -> -73243.42 | E6: (-) Impostos Contratos | H6: (-) Impostos Contratos
B7: (-) Comissões | C7: =-BD_LUCRO[[#Totals],[Comissão]] -> -2018865 | E7: (-) Comissões | H7: (-) Comissões
B8: (=) Lucro Líquido Operacional | C8: =BD_LUCRO[[#Totals],[Lucro Líq.]] -> 5627736.6 | E8: (=) Lucro Líquido Operacional | H8: (=) Lucro Líquido Operacional
B9: (-) Despesas Administrativas | C9: =-BD_DESP[[#Totals],[Valor]] -> -5011512.6 | E9: (-) Despesas Administrativas | H9: (-) Despesas Administrativas
B10: (=) LUCRO LÍQUIDO FINAL | C10: =C8+C9 -> 616224.02 | E10: (=) LUCRO LÍQUIDO FINAL | F10: =F8+F9 -> 0 | H10: (=) LUCRO LÍQUIDO FINAL | I10: =I8+I9 -> 0
B12: HISTORICO MENSAL GRUPO 2025
B13: Mês | C13: Qtde Contratos | D13: Peso Kg Total | E13: Lucro Bruto | F13: Total Frete | G13: Impostos Cont. | H13: Comissões | I13: Luc. Liq. Oper. | J13: Desp. Admin. | K13: Lucro Líq. Final | L13: Mg. Bruta % | M13: Mg. Líq. % | N13: Resultado | O13: Var. Mês Ant.
B14: Janeiro/2026 | C14: =COUNTIFS(BD_LUCRO[Mês],$B14) -> 20 | D14: =SUMIFS(BD_LUCRO[Peso Kg],BD_LUCRO[Mês],$B14) -> 1405762 | E14: =SUMIFS(BD_LUCRO[Lucro Bruto],BD_LUCRO[Mês],$B14) -> 396032.25 | F14: =SUMIFS(BD_LUCRO[Total Frete],BD_LUCRO[Mês],$B14) -> 103059.8 | G14: =SUMIFS(BD_LUCRO[Impostos],BD_LUCRO[Mês],$B14) -> 11250.02 | H14: =SUMIFS(BD_LUCRO[Comissão],BD_LUCRO[Mês],$B14) -> 18245.08 | I14: =SUMIFS(BD_LUCRO[Lucro Líq.],BD_LUCRO[Mês],$B14) -> 259819.54 | J14: =SUMIFS(BD_DESP[Valor],BD_DESP[Mês],$B14) -> 277928.94 | K14: =I14-J14 -> -18109.4 | L14: =IF(E14<>0,(E14-F14-G14-H14)/E14,0) -> 0.66529266 | M14: =IF(E14<>0,K14/E14,0) -> -0.045727084 | N14: =IF(COUNTIFS(BD_LUCRO[Mês],$B14)=0,"N/A",IF(K14>=0,"✅ POSITIVO","❌ NEGATIVO")) -> ❌ NEGATIVO | O14: -
B15: Fevereiro/2026 | C15: =COUNTIFS(BD_LUCRO[Mês],$B15) -> 36 | D15: =SUMIFS(BD_LUCRO[Peso Kg],BD_LUCRO[Mês],$B15) -> 3191522 | E15: =SUMIFS(BD_LUCRO[Lucro Bruto],BD_LUCRO[Mês],$B15) -> 642712.96 | F15: =SUMIFS(BD_LUCRO[Total Frete],BD_LUCRO[Mês],$B15) -> 37740.2 | G15: =SUMIFS(BD_LUCRO[Impostos],BD_LUCRO[Mês],$B15) -> 48781.22 | H15: =SUMIFS(BD_LUCRO[Comissão],BD_LUCRO[Mês],$B15) -> 67458.53 | I15: =SUMIFS(BD_LUCRO[Lucro Líq.],BD_LUCRO[Mês],$B15) -> 487694.56 | J15: =SUMIFS(BD_DESP[Valor],BD_DESP[Mês],$B15) -> 190770.48 | K15: =I15-J15 -> 296924.08 | L15: =IF(E15<>0,(E15-F15-G15-H15)/E15,0) -> 0.7604219 | M15: =IF(E15<>0,K15/E15,0) -> 0.46198552 | N15: =IF(COUNTIFS(BD_LUCRO[Mês],$B15)=0,"N/A",IF(K15>=0,"✅ POSITIVO","❌ NEGATIVO")) -> ✅ POSITIVO | O15: =IF(C15=0,0,IF(OR(C14=0,K14=0),0,(K15-K14)/ABS(K14))) -> 17.39613
B16: Março/2026 | C16: =COUNTIFS(BD_LUCRO[Mês],$B16) -> 21 | D16: =SUMIFS(BD_LUCRO[Peso Kg],BD_LUCRO[Mês],$B16) -> 4055398 | E16: =SUMIFS(BD_LUCRO[Lucro Bruto],BD_LUCRO[Mês],$B16) -> 630446.4 | F16: =SUMIFS(BD_LUCRO[Total Frete],BD_LUCRO[Mês],$B16) -> 17877 | G16: =SUMIFS(BD_LUCRO[Impostos],BD_LUCRO[Mês],$B16) -> 5032.61 | H16: =SUMIFS(BD_LUCRO[Comissão],BD_LUCRO[Mês],$B16) -> 69624.03 | I16: =SUMIFS(BD_LUCRO[Lucro Líq.],BD_LUCRO[Mês],$B16) -> 561581.17 | J16: =SUMIFS(BD_DESP[Valor],BD_DESP[Mês],$B16) -> 258155.2 | K16: =I16-J16 -> 303425.97 | L16: =IF(E16<>0,(E16-F16-G16-H16)/E16,0) -> 0.85322521 | M16: =IF(E16<>0,K16/E16,0) -> 0.4812875 | N16: =IF(COUNTIFS(BD_LUCRO[Mês],$B16)=0,"N/A",IF(K16>=0,"✅ POSITIVO","❌ NEGATIVO")) -> ✅ POSITIVO | O16: =IF(C16=0,0,IF(OR(C15=0,K15=0),0,(K16-K15)/ABS(K15))) -> 0.021897483
B17: Abril/2026 | C17: =COUNTIFS(BD_LUCRO[Mês],$B17) -> 8 | D17: =SUMIFS(BD_LUCRO[Peso Kg],BD_LUCRO[Mês],$B17) -> 401939 | E17: =SUMIFS(BD_LUCRO[Lucro Bruto],BD_LUCRO[Mês],$B17) -> 50857.63 | F17: =SUMIFS(BD_LUCRO[Total Frete],BD_LUCRO[Mês],$B17) -> 5010 | G17: =SUMIFS(BD_LUCRO[Impostos],BD_LUCRO[Mês],$B17) -> 897.6 | H17: =SUMIFS(BD_LUCRO[Comissão],BD_LUCRO[Mês],$B17) -> 14541.85 | I17: =SUMIFS(BD_LUCRO[Lucro Líq.],BD_LUCRO[Mês],$B17) -> 30408.19 | J17: =SUMIFS(BD_DESP[Valor],BD_DESP[Mês],$B17) -> 384352.01 | K17: =I17-J17 -> -353943.82 | L17: =IF(E17<>0,(E17-F17-G17-H17)/E17,0) -> 0.59790792 | M17: =IF(E17<>0,K17/E17,0) -> -6.9595028 | N17: =IF(COUNTIFS(BD_LUCRO[Mês],$B17)=0,"N/A",IF(K17>=0,"✅ POSITIVO","❌ NEGATIVO")) -> ❌ NEGATIVO | O17: =IF(C17=0,0,IF(OR(C16=0,K16=0),0,(K17-K16)/ABS(K16))) -> -2.1664915
B18: Maio/2026 | C18: =COUNTIFS(BD_LUCRO[Mês],$B18) -> 1 | D18: =SUMIFS(BD_LUCRO[Peso Kg],BD_LUCRO[Mês],$B18) -> 1959060 | E18: =SUMIFS(BD_LUCRO[Lucro Bruto],BD_LUCRO[Mês],$B18) -> 111013.4 | F18: =SUMIFS(BD_LUCRO[Total Frete],BD_LUCRO[Mês],$B18) -> 0 | G18: =SUMIFS(BD_LUCRO[Impostos],BD_LUCRO[Mês],$B18) -> 0 | H18: =SUMIFS(BD_LUCRO[Comissão],BD_LUCRO[Mês],$B18) -> 22855.7 | I18: =SUMIFS(BD_LUCRO[Lucro Líq.],BD_LUCRO[Mês],$B18) -> 88157.7 | J18: =SUMIFS(BD_DESP[Valor],BD_DESP[Mês],$B18) -> 222799.21 | K18: =I18-J18 -> -134641.51 | L18: =IF(E18<>0,(E18-F18-G18-H18)/E18,0) -> 0.79411765 | M18: =IF(E18<>0,K18/E18,0) -> -1.2128402 | N18: =IF(COUNTIFS(BD_LUCRO[Mês],$B18)=0,"N/A",IF(K18>=0,"✅ POSITIVO","❌ NEGATIVO")) -> ❌ NEGATIVO | O18: =IF(C18=0,0,IF(OR(C17=0,K17=0),0,(K18-K17)/ABS(K17))) -> 0.61959638
B19: Junho/2026 | C19: =COUNTIFS(BD_LUCRO[Mês],$B19) -> 0 | D19: =SUMIFS(BD_LUCRO[Peso Kg],BD_LUCRO[Mês],$B19) -> 0 | E19: =SUMIFS(BD_LUCRO[Lucro Bruto],BD_LUCRO[Mês],$B19) -> 0 | F19: =SUMIFS(BD_LUCRO[Total Frete],BD_LUCRO[Mês],$B19) -> 0 | G19: =SUMIFS(BD_LUCRO[Impostos],BD_LUCRO[Mês],$B19) -> 0 | H19: =SUMIFS(BD_LUCRO[Comissão],BD_LUCRO[Mês],$B19) -> 0 | I19: =SUMIFS(BD_LUCRO[Lucro Líq.],BD_LUCRO[Mês],$B19) -> 0 | J19: =SUMIFS(BD_DESP[Valor],BD_DESP[Mês],$B19) -> 0 | K19: =I19-J19 -> 0 | L19: =IF(E19<>0,(E19-F19-G19-H19)/E19,0) -> 0 | M19: =IF(E19<>0,K19/E19,0) -> 0 | N19: =IF(COUNTIFS(BD_LUCRO[Mês],$B19)=0,"N/A",IF(K19>=0,"✅ POSITIVO","❌ NEGATIVO")) -> N/A | O19: =IF(C19=0,0,IF(OR(C18=0,K18=0),0,(K19-K18)/ABS(K18))) -> 0
B20: Julho/2026 | C20: =COUNTIFS(BD_LUCRO[Mês],$B20) -> 0 | D20: =SUMIFS(BD_LUCRO[Peso Kg],BD_LUCRO[Mês],$B20) -> 0 | E20: =SUMIFS(BD_LUCRO[Lucro Bruto],BD_LUCRO[Mês],$B20) -> 0 | F20: =SUMIFS(BD_LUCRO[Total Frete],BD_LUCRO[Mês],$B20) -> 0 | G20: =SUMIFS(BD_LUCRO[Impostos],BD_LUCRO[Mês],$B20) -> 0 | H20: =SUMIFS(BD_LUCRO[Comissão],BD_LUCRO[Mês],$B20) -> 0 | I20: =SUMIFS(BD_LUCRO[Lucro Líq.],BD_LUCRO[Mês],$B20) -> 0 | J20: =SUMIFS(BD_DESP[Valor],BD_DESP[Mês],$B20) -> 0 | K20: =I20-J20 -> 0 | L20: =IF(E20<>0,(E20-F20-G20-H20)/E20,0) -> 0 | M20: =IF(E20<>0,K20/E20,0) -> 0 | N20: =IF(COUNTIFS(BD_LUCRO[Mês],$B20)=0,"N/A",IF(K20>=0,"✅ POSITIVO","❌ NEGATIVO")) -> N/A | O20: =IF(C20=0,0,IF(OR(C19=0,K19=0),0,(K20-K19)/ABS(K19))) -> 0
B21: Agosto/2026 | C21: =COUNTIFS(BD_LUCRO[Mês],$B21) -> 0 | D21: =SUMIFS(BD_LUCRO[Peso Kg],BD_LUCRO[Mês],$B21) -> 0 | E21: =SUMIFS(BD_LUCRO[Lucro Bruto],BD_LUCRO[Mês],$B21) -> 0 | F21: =SUMIFS(BD_LUCRO[Total Frete],BD_LUCRO[Mês],$B21) -> 0 | G21: =SUMIFS(BD_LUCRO[Impostos],BD_LUCRO[Mês],$B21) -> 0 | H21: =SUMIFS(BD_LUCRO[Comissão],BD_LUCRO[Mês],$B21) -> 0 | I21: =SUMIFS(BD_LUCRO[Lucro Líq.],BD_LUCRO[Mês],$B21) -> 0 | J21: =SUMIFS(BD_DESP[Valor],BD_DESP[Mês],$B21) -> 0 | K21: =I21-J21 -> 0 | L21: =IF(E21<>0,(E21-F21-G21-H21)/E21,0) -> 0 | M21: =IF(E21<>0,K21/E21,0) -> 0 | N21: =IF(COUNTIFS(BD_LUCRO[Mês],$B21)=0,"N/A",IF(K21>=0,"✅ POSITIVO","❌ NEGATIVO")) -> N/A | O21: =IF(C21=0,0,IF(OR(C20=0,K20=0),0,(K21-K20)/ABS(K20))) -> 0
B22: Setembro/2026 | C22: =COUNTIFS(BD_LUCRO[Mês],$B22) -> 0 | D22: =SUMIFS(BD_LUCRO[Peso Kg],BD_LUCRO[Mês],$B22) -> 0 | E22: =SUMIFS(BD_LUCRO[Lucro Bruto],BD_LUCRO[Mês],$B22) -> 0 | F22: =SUMIFS(BD_LUCRO[Total Frete],BD_LUCRO[Mês],$B22) -> 0 | G22: =SUMIFS(BD_LUCRO[Impostos],BD_LUCRO[Mês],$B22) -> 0 | H22: =SUMIFS(BD_LUCRO[Comissão],BD_LUCRO[Mês],$B22) -> 0 | I22: =SUMIFS(BD_LUCRO[Lucro Líq.],BD_LUCRO[Mês],$B22) -> 0 | J22: =SUMIFS(BD_DESP[Valor],BD_DESP[Mês],$B22) -> 0 | K22: =I22-J22 -> 0 | L22: =IF(E22<>0,(E22-F22-G22-H22)/E22,0) -> 0 | M22: =IF(E22<>0,K22/E22,0) -> 0 | N22: =IF(COUNTIFS(BD_LUCRO[Mês],$B22)=0,"N/A",IF(K22>=0,"✅ POSITIVO","❌ NEGATIVO")) -> N/A | O22: =IF(C22=0,0,IF(OR(C21=0,K21=0),0,(K22-K21)/ABS(K21))) -> 0
B23: Outubro/2026 | C23: =COUNTIFS(BD_LUCRO[Mês],$B23) -> 0 | D23: =SUMIFS(BD_LUCRO[Peso Kg],BD_LUCRO[Mês],$B23) -> 0 | E23: =SUMIFS(BD_LUCRO[Lucro Bruto],BD_LUCRO[Mês],$B23) -> 0 | F23: =SUMIFS(BD_LUCRO[Total Frete],BD_LUCRO[Mês],$B23) -> 0 | G23: =SUMIFS(BD_LUCRO[Impostos],BD_LUCRO[Mês],$B23) -> 0 | H23: =SUMIFS(BD_LUCRO[Comissão],BD_LUCRO[Mês],$B23) -> 0 | I23: =SUMIFS(BD_LUCRO[Lucro Líq.],BD_LUCRO[Mês],$B23) -> 0 | J23: =SUMIFS(BD_DESP[Valor],BD_DESP[Mês],$B23) -> 0 | K23: =I23-J23 -> 0 | L23: =IF(E23<>0,(E23-F23-G23-H23)/E23,0) -> 0 | M23: =IF(E23<>0,K23/E23,0) -> 0 | N23: =IF(COUNTIFS(BD_LUCRO[Mês],$B23)=0,"N/A",IF(K23>=0,"✅ POSITIVO","❌ NEGATIVO")) -> N/A | O23: =IF(C23=0,0,IF(OR(C22=0,K22=0),0,(K23-K22)/ABS(K22))) -> 0
B24: Novembro/2026 | C24: =COUNTIFS(BD_LUCRO[Mês],$B24) -> 0 | D24: =SUMIFS(BD_LUCRO[Peso Kg],BD_LUCRO[Mês],$B24) -> 0 | E24: =SUMIFS(BD_LUCRO[Lucro Bruto],BD_LUCRO[Mês],$B24) -> 0 | F24: =SUMIFS(BD_LUCRO[Total Frete],BD_LUCRO[Mês],$B24) -> 0 | G24: =SUMIFS(BD_LUCRO[Impostos],BD_LUCRO[Mês],$B24) -> 0 | H24: =SUMIFS(BD_LUCRO[Comissão],BD_LUCRO[Mês],$B24) -> 0 | I24: =SUMIFS(BD_LUCRO[Lucro Líq.],BD_LUCRO[Mês],$B24) -> 0 | J24: =SUMIFS(BD_DESP[Valor],BD_DESP[Mês],$B24) -> 0 | K24: =I24-J24 -> 0 | L24: =IF(E24<>0,(E24-F24-G24-H24)/E24,0) -> 0 | M24: =IF(E24<>0,K24/E24,0) -> 0 | N24: =IF(COUNTIFS(BD_LUCRO[Mês],$B24)=0,"N/A",IF(K24>=0,"✅ POSITIVO","❌ NEGATIVO")) -> N/A | O24: =IF(C24=0,0,IF(OR(C23=0,K23=0),0,(K24-K23)/ABS(K23))) -> 0
B25: Dezembro/2026 | C25: =COUNTIFS(BD_LUCRO[Mês],$B25) -> 0 | D25: =SUMIFS(BD_LUCRO[Peso Kg],BD_LUCRO[Mês],$B25) -> 0 | E25: =SUMIFS(BD_LUCRO[Lucro Bruto],BD_LUCRO[Mês],$B25) -> 0 | F25: =SUMIFS(BD_LUCRO[Total Frete],BD_LUCRO[Mês],$B25) -> 0 | G25: =SUMIFS(BD_LUCRO[Impostos],BD_LUCRO[Mês],$B25) -> 0 | H25: =SUMIFS(BD_LUCRO[Comissão],BD_LUCRO[Mês],$B25) -> 0 | I25: =SUMIFS(BD_LUCRO[Lucro Líq.],BD_LUCRO[Mês],$B25) -> 0 | J25: =SUMIFS(BD_DESP[Valor],BD_DESP[Mês],$B25) -> 0 | K25: =I25-J25 -> 0 | L25: =IF(E25<>0,(E25-F25-G25-H25)/E25,0) -> 0 | M25: =IF(E25<>0,K25/E25,0) -> 0 | N25: =IF(COUNTIFS(BD_LUCRO[Mês],$B25)=0,"N/A",IF(K25>=0,"✅ POSITIVO","❌ NEGATIVO")) -> N/A | O25: =IF(C25=0,0,IF(OR(C24=0,K24=0),0,(K25-K24)/ABS(K24))) -> 0
B26: TOTAL ANUAL 2026 | C26: =SUM(C14:C25) -> 86 | D26: =SUM(D14:D25) -> 11013681 | E26: =SUM(E14:E25) -> 1831062.6 | F26: =SUM(F14:F25) -> 163687 | G26: =SUM(G14:G25) -> 65961.45 | H26: =SUM(H14:H25) -> 192725.19 | I26: =SUM(I14:I25) -> 1427661.2 | J26: =SUM(J14:J25) -> 1334005.8 | K26: =SUM(K14:K25) -> 93655.32 | L26: =IF(E26<>0,(E26-F26-G26-H26)/E26,0) -> 0.76932868 | M26: =IF(E26<>0,K26/E26,0) -> 0.05114807 | N26: =IF(K26>=0,"✅ POSITIVO","❌ NEGATIVO") -> ✅ POSITIVO | O26: -
B28: HISTÓRICO MENSAL GRUPO 2025
B29: Mês | C29: Qtde Contratos | D29: Peso Kg Total | E29: Lucro Bruto | F29: Total Frete | G29: Impostos Cont. | H29: Comissões | I29: Luc. Liq. Oper. | J29: Desp. Admin. | K29: Lucro Líq. Final | L29: Mg. Bruta % | M29: Mg. Líq. % | N29: Resultado | O29: Var. Mês Ant.
B30: Janeiro/2025 | C30: =COUNTIFS(BD_LUCRO[Mês],$B30) -> 5 | D30: =SUMIFS(BD_LUCRO[Peso Kg],BD_LUCRO[Mês],$B30) -> 1446450 | E30: =SUMIFS(BD_LUCRO[Lucro Bruto],BD_LUCRO[Mês],$B30) -> 347078.94 | F30: =SUMIFS(BD_LUCRO[Total Frete],BD_LUCRO[Mês],$B30) -> 212796.84 | G30: =SUMIFS(BD_LUCRO[Impostos],BD_LUCRO[Mês],$B30) -> 3518.06 | H30: =SUMIFS(BD_LUCRO[Comissão],BD_LUCRO[Mês],$B30) -> 11539.87 | I30: =SUMIFS(BD_LUCRO[Lucro Líq.],BD_LUCRO[Mês],$B30) -> 106231.7 | J30: =SUMIFS(BD_DESP[Valor],BD_DESP[Mês],$B30) -> 267317.77 | K30: =I30-J30 -> -161086.07 | L30: =IF(E30<>0,(E30-F30-G30-H30)/E30,0) -> 0.34350736 | M30: =IF(E30<>0,K30/E30,0) -> -0.4641194 | N30: =IF(COUNTIFS(BD_LUCRO[Mês],$B30)=0,"N/A",IF(K30>=0,"✅ POSITIVO","❌ NEGATIVO")) -> ❌ NEGATIVO | O30: -
B31: Fevereiro/2025 | C31: =COUNTIFS(BD_LUCRO[Mês],$B31) -> 13 | D31: =SUMIFS(BD_LUCRO[Peso Kg],BD_LUCRO[Mês],$B31) -> 1787495 | E31: =SUMIFS(BD_LUCRO[Lucro Bruto],BD_LUCRO[Mês],$B31) -> 781745.28 | F31: =SUMIFS(BD_LUCRO[Total Frete],BD_LUCRO[Mês],$B31) -> 0 | G31: =SUMIFS(BD_LUCRO[Impostos],BD_LUCRO[Mês],$B31) -> 1064.6 | H31: =SUMIFS(BD_LUCRO[Comissão],BD_LUCRO[Mês],$B31) -> 13556.84 | I31: =SUMIFS(BD_LUCRO[Lucro Líq.],BD_LUCRO[Mês],$B31) -> 716883.4 | J31: =SUMIFS(BD_DESP[Valor],BD_DESP[Mês],$B31) -> 142974.87 | K31: =I31-J31 -> 573908.53 | L31: =IF(E31<>0,(E31-F31-G31-H31)/E31,0) -> 0.98129641 | M31: =IF(E31<>0,K31/E31,0) -> 0.73413751 | N31: =IF(COUNTIFS(BD_LUCRO[Mês],$B31)=0,"N/A",IF(K31>=0,"✅ POSITIVO","❌ NEGATIVO")) -> ✅ POSITIVO | O31: =IF(K30<>0,(K31-K30)/ABS(K30),0) -> 4.5627446
B32: Março/2025 | C32: =COUNTIFS(BD_LUCRO[Mês],$B32) -> 18 | D32: =SUMIFS(BD_LUCRO[Peso Kg],BD_LUCRO[Mês],$B32) -> 3981807 | E32: =SUMIFS(BD_LUCRO[Lucro Bruto],BD_LUCRO[Mês],$B32) -> 1689268 | F32: =SUMIFS(BD_LUCRO[Total Frete],BD_LUCRO[Mês],$B32) -> 432839.6 | G32: =SUMIFS(BD_LUCRO[Impostos],BD_LUCRO[Mês],$B32) -> 0 | H32: =SUMIFS(BD_LUCRO[Comissão],BD_LUCRO[Mês],$B32) -> 99575.07 | I32: =SUMIFS(BD_LUCRO[Lucro Líq.],BD_LUCRO[Mês],$B32) -> 1154496.8 | J32: =SUMIFS(BD_DESP[Valor],BD_DESP[Mês],$B32) -> 180047.93 | K32: =I32-J32 -> 974448.91 | L32: =IF(E32<>0,(E32-F32-G32-H32)/E32,0) -> 0.68482521 | M32: =IF(E32<>0,K32/E32,0) -> 0.57684686 | N32: =IF(COUNTIFS(BD_LUCRO[Mês],$B32)=0,"N/A",IF(K32>=0,"✅ POSITIVO","❌ NEGATIVO")) -> ✅ POSITIVO | O32: =IF(K31<>0,(K32-K31)/ABS(K31),0) -> 0.69791676
B33: Abril/2025 | C33: =COUNTIFS(BD_LUCRO[Mês],$B33) -> 13 | D33: =SUMIFS(BD_LUCRO[Peso Kg],BD_LUCRO[Mês],$B33) -> 4701587 | E33: =SUMIFS(BD_LUCRO[Lucro Bruto],BD_LUCRO[Mês],$B33) -> 1264396.6 | F33: =SUMIFS(BD_LUCRO[Total Frete],BD_LUCRO[Mês],$B33) -> 623905.38 | G33: =SUMIFS(BD_LUCRO[Impostos],BD_LUCRO[Mês],$B33) -> 0 | H33: =SUMIFS(BD_LUCRO[Comissão],BD_LUCRO[Mês],$B33) -> 140516.21 | I33: =SUMIFS(BD_LUCRO[Lucro Líq.],BD_LUCRO[Mês],$B33) -> 499270.09 | J33: =SUMIFS(BD_DESP[Valor],BD_DESP[Mês],$B33) -> 354429.39 | K33: =I33-J33 -> 144840.7 | L33: =IF(E33<>0,(E33-F33-G33-H33)/E33,0) -> 0.39542576 | M33: =IF(E33<>0,K33/E33,0) -> 0.11455322 | N33: =IF(COUNTIFS(BD_LUCRO[Mês],$B33)=0,"N/A",IF(K33>=0,"✅ POSITIVO","❌ NEGATIVO")) -> ✅ POSITIVO | O33: =IF(K32<>0,(K33-K32)/ABS(K32),0) -> -0.85136142
B34: Maio/2025 | C34: =COUNTIFS(BD_LUCRO[Mês],$B34) -> 10 | D34: =SUMIFS(BD_LUCRO[Peso Kg],BD_LUCRO[Mês],$B34) -> 2738898 | E34: =SUMIFS(BD_LUCRO[Lucro Bruto],BD_LUCRO[Mês],$B34) -> 713587.7 | F34: =SUMIFS(BD_LUCRO[Total Frete],BD_LUCRO[Mês],$B34) -> 181454.79 | G34: =SUMIFS(BD_LUCRO[Impostos],BD_LUCRO[Mês],$B34) -> 637.16 | H34: =SUMIFS(BD_LUCRO[Comissão],BD_LUCRO[Mês],$B34) -> 19763.06 | I34: =SUMIFS(BD_LUCRO[Lucro Líq.],BD_LUCRO[Mês],$B34) -> 520095.42 | J34: =SUMIFS(BD_DESP[Valor],BD_DESP[Mês],$B34) -> 137831.58 | K34: =I34-J34 -> 382263.84 | L34: =IF(E34<>0,(E34-F34-G34-H34)/E34,0) -> 0.71712656 | M34: =IF(E34<>0,K34/E34,0) -> 0.53569287 | N34: =IF(COUNTIFS(BD_LUCRO[Mês],$B34)=0,"N/A",IF(K34>=0,"✅ POSITIVO","❌ NEGATIVO")) -> ✅ POSITIVO | O34: =IF(K33<>0,(K34-K33)/ABS(K33),0) -> 1.6392018
B35: Junho/2025 | C35: =COUNTIFS(BD_LUCRO[Mês],$B35) -> 8 | D35: =SUMIFS(BD_LUCRO[Peso Kg],BD_LUCRO[Mês],$B35) -> 1853380 | E35: =SUMIFS(BD_LUCRO[Lucro Bruto],BD_LUCRO[Mês],$B35) -> 92136.99 | F35: =SUMIFS(BD_LUCRO[Total Frete],BD_LUCRO[Mês],$B35) -> 351139.42 | G35: =SUMIFS(BD_LUCRO[Impostos],BD_LUCRO[Mês],$B35) -> 15779.23 | H35: =SUMIFS(BD_LUCRO[Comissão],BD_LUCRO[Mês],$B35) -> 197665.77 | I35: =SUMIFS(BD_LUCRO[Lucro Líq.],BD_LUCRO[Mês],$B35) -> 60153.78 | J35: =SUMIFS(BD_DESP[Valor],BD_DESP[Mês],$B35) -> 259224.64 | K35: =I35-J35 -> -199070.86 | L35: =IF(E35<>0,(E35-F35-G35-H35)/E35,0) -> -5.127663 | M35: =IF(E35<>0,K35/E35,0) -> -2.1605965 | N35: =IF(COUNTIFS(BD_LUCRO[Mês],$B35)=0,"N/A",IF(K35>=0,"✅ POSITIVO","❌ NEGATIVO")) -> ❌ NEGATIVO | O35: =IF(K34<>0,(K35-K34)/ABS(K34),0) -> -1.5207682
B36: Julho/2025 | C36: =COUNTIFS(BD_LUCRO[Mês],$B36) -> 5 | D36: =SUMIFS(BD_LUCRO[Peso Kg],BD_LUCRO[Mês],$B36) -> 754300 | E36: =SUMIFS(BD_LUCRO[Lucro Bruto],BD_LUCRO[Mês],$B36) -> 0 | F36: =SUMIFS(BD_LUCRO[Total Frete],BD_LUCRO[Mês],$B36) -> 242622.45 | G36: =SUMIFS(BD_LUCRO[Impostos],BD_LUCRO[Mês],$B36) -> -69880.18 | H36: =SUMIFS(BD_LUCRO[Comissão],BD_LUCRO[Mês],$B36) -> 393437.97 | I36: =SUMIFS(BD_LUCRO[Lucro Líq.],BD_LUCRO[Mês],$B36) -> 93877.56 | J36: =SUMIFS(BD_DESP[Valor],BD_DESP[Mês],$B36) -> 713342.74 | K36: =I36-J36 -> -619465.18 | L36: =IF(E36<>0,(E36-F36-G36-H36)/E36,0) -> 0 | M36: =IF(E36<>0,K36/E36,0) -> 0 | N36: =IF(COUNTIFS(BD_LUCRO[Mês],$B36)=0,"N/A",IF(K36>=0,"✅ POSITIVO","❌ NEGATIVO")) -> ❌ NEGATIVO | O36: =IF(K35<>0,(K36-K35)/ABS(K35),0) -> -2.1117823
B37: Agosto/2025 | C37: =COUNTIFS(BD_LUCRO[Mês],$B37) -> 11 | D37: =SUMIFS(BD_LUCRO[Peso Kg],BD_LUCRO[Mês],$B37) -> 1484382 | E37: =SUMIFS(BD_LUCRO[Lucro Bruto],BD_LUCRO[Mês],$B37) -> 847503.9 | F37: =SUMIFS(BD_LUCRO[Total Frete],BD_LUCRO[Mês],$B37) -> 306565.3 | G37: =SUMIFS(BD_LUCRO[Impostos],BD_LUCRO[Mês],$B37) -> 6852.62 | H37: =SUMIFS(BD_LUCRO[Comissão],BD_LUCRO[Mês],$B37) -> 397616.86 | I37: =SUMIFS(BD_LUCRO[Lucro Líq.],BD_LUCRO[Mês],$B37) -> 357771.6 | J37: =SUMIFS(BD_DESP[Valor],BD_DESP[Mês],$B37) -> 480656.74 | K37: =I37-J37 -> -122885.14 | L37: =IF(E37<>0,(E37-F37-G37-H37)/E37,0) -> 0.16102477 | M37: =IF(E37<>0,K37/E37,0) -> -0.14499655 | N37: =IF(COUNTIFS(BD_LUCRO[Mês],$B37)=0,"N/A",IF(K37>=0,"✅ POSITIVO","❌ NEGATIVO")) -> ❌ NEGATIVO | O37: =IF(K36<>0,(K37-K36)/ABS(K36),0) -> 0.80162704
B38: Setembro/2025 | C38: =COUNTIFS(BD_LUCRO[Mês],$B38) -> 12 | D38: =SUMIFS(BD_LUCRO[Peso Kg],BD_LUCRO[Mês],$B38) -> 2623460 | E38: =SUMIFS(BD_LUCRO[Lucro Bruto],BD_LUCRO[Mês],$B38) -> 432526.47 | F38: =SUMIFS(BD_LUCRO[Total Frete],BD_LUCRO[Mês],$B38) -> 205826.1 | G38: =SUMIFS(BD_LUCRO[Impostos],BD_LUCRO[Mês],$B38) -> 14225.53 | H38: =SUMIFS(BD_LUCRO[Comissão],BD_LUCRO[Mês],$B38) -> 464.8 | I38: =SUMIFS(BD_LUCRO[Lucro Líq.],BD_LUCRO[Mês],$B38) -> 207587.74 | J38: =SUMIFS(BD_DESP[Valor],BD_DESP[Mês],$B38) -> 331951.65 | K38: =I38-J38 -> -124363.91 | L38: =IF(E38<>0,(E38-F38-G38-H38)/E38,0) -> 0.49016662 | M38: =IF(E38<>0,K38/E38,0) -> -0.28752902 | N38: =IF(COUNTIFS(BD_LUCRO[Mês],$B38)=0,"N/A",IF(K38>=0,"✅ POSITIVO","❌ NEGATIVO")) -> ❌ NEGATIVO | O38: =IF(K37<>0,(K38-K37)/ABS(K37),0) -> -0.012033758
B39: Outubro/2025 | C39: =COUNTIFS(BD_LUCRO[Mês],$B39) -> 12 | D39: =SUMIFS(BD_LUCRO[Peso Kg],BD_LUCRO[Mês],$B39) -> 1559400 | E39: =SUMIFS(BD_LUCRO[Lucro Bruto],BD_LUCRO[Mês],$B39) -> 193668.13 | F39: =SUMIFS(BD_LUCRO[Total Frete],BD_LUCRO[Mês],$B39) -> 279111.15 | G39: =SUMIFS(BD_LUCRO[Impostos],BD_LUCRO[Mês],$B39) -> 6172.99 | H39: =SUMIFS(BD_LUCRO[Comissão],BD_LUCRO[Mês],$B39) -> 541462.79 | I39: =SUMIFS(BD_LUCRO[Lucro Líq.],BD_LUCRO[Mês],$B39) -> 233803.58 | J39: =SUMIFS(BD_DESP[Valor],BD_DESP[Mês],$B39) -> 178639.79 | K39: =I39-J39 -> 55163.79 | L39: =IF(E39<>0,(E39-F39-G39-H39)/E39,0) -> -3.2688848 | M39: =IF(E39<>0,K39/E39,0) -> 0.28483669 | N39: =IF(COUNTIFS(BD_LUCRO[Mês],$B39)=0,"N/A",IF(K39>=0,"✅ POSITIVO","❌ NEGATIVO")) -> ✅ POSITIVO | O39: =IF(K38<>0,(K39-K38)/ABS(K38),0) -> 1.4435675
B40: Novembro/2025 | C40: =COUNTIFS(BD_LUCRO[Mês],$B40) -> 13 | D40: =SUMIFS(BD_LUCRO[Peso Kg],BD_LUCRO[Mês],$B40) -> 2024100 | E40: =SUMIFS(BD_LUCRO[Lucro Bruto],BD_LUCRO[Mês],$B40) -> 288046.53 | F40: =SUMIFS(BD_LUCRO[Total Frete],BD_LUCRO[Mês],$B40) -> 216594.87 | G40: =SUMIFS(BD_LUCRO[Impostos],BD_LUCRO[Mês],$B40) -> 14242.64 | H40: =SUMIFS(BD_LUCRO[Comissão],BD_LUCRO[Mês],$B40) -> 7019.6 | I40: =SUMIFS(BD_LUCRO[Lucro Líq.],BD_LUCRO[Mês],$B40) -> 165851.95 | J40: =SUMIFS(BD_DESP[Valor],BD_DESP[Mês],$B40) -> 325465.06 | K40: =I40-J40 -> -159613.11 | L40: =IF(E40<>0,(E40-F40-G40-H40)/E40,0) -> 0.17424067 | M40: =IF(E40<>0,K40/E40,0) -> -0.55412266 | N40: =IF(COUNTIFS(BD_LUCRO[Mês],$B40)=0,"N/A",IF(K40>=0,"✅ POSITIVO","❌ NEGATIVO")) -> ❌ NEGATIVO | O40: =IF(K39<>0,(K40-K39)/ABS(K39),0) -> -3.8934399
B41: Dezembro/2025 | C41: =COUNTIFS(BD_LUCRO[Mês],$B41) -> 4 | D41: =SUMIFS(BD_LUCRO[Peso Kg],BD_LUCRO[Mês],$B41) -> 761240 | E41: =SUMIFS(BD_LUCRO[Lucro Bruto],BD_LUCRO[Mês],$B41) -> 315994.2 | F41: =SUMIFS(BD_LUCRO[Total Frete],BD_LUCRO[Mês],$B41) -> 206315.9 | G41: =SUMIFS(BD_LUCRO[Impostos],BD_LUCRO[Mês],$B41) -> 14669.32 | H41: =SUMIFS(BD_LUCRO[Comissão],BD_LUCRO[Mês],$B41) -> 3521 | I41: =SUMIFS(BD_LUCRO[Lucro Líq.],BD_LUCRO[Mês],$B41) -> 84051.78 | J41: =SUMIFS(BD_DESP[Valor],BD_DESP[Mês],$B41) -> 305624.58 | K41: =I41-J41 -> -221572.8 | L41: =IF(E41<>0,(E41-F41-G41-H41)/E41,0) -> 0.28952424 | M41: =IF(E41<>0,K41/E41,0) -> -0.70119262 | N41: =IF(COUNTIFS(BD_LUCRO[Mês],$B41)=0,"N/A",IF(K41>=0,"✅ POSITIVO","❌ NEGATIVO")) -> ❌ NEGATIVO | O41: =IF(K40<>0,(K41-K40)/ABS(K40),0) -> -0.38818672
B42: TOTAL ANUAL 2025 | C42: =SUM(C30:C41) -> 124 | D42: =SUM(D30:D41) -> 25716499 | E42: =SUM(E30:E41) -> 6965952.7 | F42: =SUM(F30:F41) -> 3259171.8 | G42: =SUM(G30:G41) -> 7281.97 | H42: =SUM(H30:H41) -> 1826139.8 | I42: =SUM(I30:I41) -> 4200075.4 | J42: =SUM(J30:J41) -> 3677506.7 | K42: =SUM(K30:K41) -> 522568.7 | L42: =IF(E42<>0,(E42-F42-G42-H42)/E42,0) -> 0.26893078 | M42: =IF(E42<>0,K42/E42,0) -> 0.07501755 | N42: =IF(K42>=0,"✅ POSITIVO","❌ NEGATIVO") -> ✅ POSITIVO | O42: -

Sheet BD_FATURAMENTO
A1: Empresa | B1: Data | C1: Num Carregamento | D1: Placa | E1: Nota Fiscal | F1: Peso | G1: Valor Venda | H1: Valor Compra | I1: Frete | J1: Impostos | K1: Outros Gastos | L1: Lucro Contrato
A2: BC_MATRIZ | B2: 46029 | C2: 2205 | D2: QCM-7I13 | E2: 1982 | F2: 51920 | G2: 57024 | H2: 38074.67 | I2: 12870 | J2: 1183.78 | K2: 689.2 | L2: 4206.35
A3: BC_MATRIZ | B3: 46030 | C3: 2207 | D3: BCZ-9H95 | E3: 1985 | F3: 51960 | G3: 56936 | H3: 38104 | I3: 12202.4 | J3: 1247.04 | K3: 689.6 | L3: 4692.96
A4: BC_MATRIZ | B4: 46030 | C4: 2208 | D4: GAT-4401 | E4: 1984 | F4: 52200 | G4: 57354 | H4: 38280 | I4: 12438 | J4: 1252.8 | K4: 692 | L4: 4691.2
A5: BC_MATRIZ | B5: 46030 | C5: 2209 | D5: RAH-4J85 | E5: 1983 | F5: 50340 | G5: 55242 | H5: 36916 | I5: 11991.6 | J5: 1208.16 | K5: 673.4 | L5: 4452.84
A6: BC_MATRIZ | B6: 46030 | C6: 2210 | D6: BEB-4B05 | E6: 1986 | F6: 50560 | G6: 55352 | H6: 37077.33 | I6: 11812.8 | J6: 1213.44 | K6: 675.6 | L6: 4572.83
A7: BC_MATRIZ | B7: 46035 | C7: 2211 | D7: IPF-6F38 | E7: 1988 | F7: 39960 | G7: 53067 | H7: 37562.4 | I7: 9885 | J7: 1352.25 | K7: 1169 | L7: 3098.35
A8: BC_MATRIZ | B8: 46035 | C8: 2212 | D8: JVT-5469 | E8: 1987 | F8: 41300 | G8: 54796 | H8: 38822 | I8: 10210 | J8: 1397.59 | K8: 1202.5 | L8: 3163.91
A9: BC_MATRIZ | B9: 46037 | C9: 2213 | D9: MLX-4178 | E9: 1989 | F9: 50720 | G9: 55902 | H9: 37194.67 | I9: 12590 | J9: 1156.42 | K9: 677.2 | L9: 4283.71
A10: BC_MATRIZ | B10: 46038 | C10: 2214 | D10: NZB-5J49 | E10: 1990 | F10: 36600 | G10: 48678 | H10: 34404 | I10: 9060 | J10: 1238.54 | K10: 1085 | L10: 2890.46
A11: BC_MATRIZ | B11: 46052 | C11: 2247 | D11: XXX-9999 | E11: 1991 | F11: 43661 | G11: 80045.17 | H11: 60584.15 | I11: 0 | J11: 0 | K11: 727.68 | L11: 18733.33
A12: BC_MATRIZ | B12: 46053 | C12: 2246 | D12: XXX-9999 | E12: 1993 | F12: 62088 | G12: 113828 | H12: 96546.84 | I12: 0 | J12: 0 | K12: 4139.2 | L12: 13141.96
A13: MM | B13: 46039 | C13: 2215 | D13: XXX-9999 | E13: 1567 | F13: 62982 | G13: 113367.6 | H13: 82128.53 | I13: 0 | J13: 0 | K13: 0 | L13: 31239.07
... A21: MM | B21: 46043 | C21: 2232 | D21: XXX-9999 | E21: 1570 | F21: 6564 | G21: 11705.8 | H21: 11301.02 | I21: 0 | J21: 0 | K21: 92.29 | L21: 312.49
A22: MM | B22: 46043 | C22: 2233 | D22: XXX-9999 | E22: 1570/1585/1586/1587/1588/1589 | F22: 6030 | G22: 10753.5 | H22: 10482.15 | I22: 0 | J22: 0 | K22: 84.78 | L22: 186.57
A23: MM | B23: 46043 | C23: 2235 | D23: XXX-9999 | E23: 1570 | F23: 27035 | G23: 47761.83 | H23: 46995.84 | I23: 0 | J23: 0 | K23: 380.11 | L23: 385.88
A24: MM | B24: 46045 | C24: 2226 | D24: XXX-9999 | E24: 1573 | F24: 56322 | G24: 100440.9 | H24: 96967.71 | I24: 0 | J24: 0 | K24: 1032.57 | L24: 2440.62
A25: MM | B25: 46045 | C25: 2229 | D25: XXX-9999 | E25: 1574 | F25: 3678 | G25: 6559.1 | H25: 6332.29 | I25: 0 | J25: 0 | K25: 67.43 | L25: 159.38
A26: MM | B26: 46045 | C26: 2230 | D26: XXX-9999 | E26: 1574 | F26: 33167 | G26: 59147.82 | H26: 54338.6 | I26: 0 | J26: 0 | K26: 630.17 | L26: 4179.04
A27: MM | B27: 46046 | C27: 2231 | D27: XXX-9999 | E27: 1577 | F27: 36379 | G27: 64875.88 | H27: 62632.51 | I27: 0 | J27: 0 | K27: 511.49 | L27: 1731.88
A28: MM | B28: 46046 | C28: 2236 | D28: XXX-9999 | E28: 1576 | F28: 26935 | G28: 47585.17 | H28: 46822.01 | I28: 0 | J28: 0 | K28: 378.71 | L28: 384.45
A29: MM | B29: 46046 | C29: 2237 | D29: XXX-9999 | E29: 1576 | F29: 11087 | G29: 19587.03 | H29: 19272.9 | I29: 0 | J29: 0 | K29: 203.26 | L29: 110.87
A30: MM | B30: 46047 | C30: 2238 | D30: XXX-9999 | E30: 1579 | F30: 4777 | G30: 8439.37 | H30: 8304.02 | I30: 0 | J30: 0 | K30: 87.58 | L30: 47.77
A31: MM | B31: 46047 | C31: 2239 | D31: XXX-9999 | E31: 1579 | F31: 33944 | G31: 59967.73 | H31: 56573.33 | I31: 0 | J31: 0 | K31: 1114.44 | L31: 2279.96
A32: MM | B32: 46048 | C32: 2240 | D32: XXX-9999 | E32: 1580/1590/1591 | F32: 16222 | G32: 28658.87 | H32: 27036.67 | I32: 0 | J32: 0 | K32: 300.11 | L32: 1322.09
A33: MM | B33: 46048 | C33: 2241 | D33: XXX-9999 | E33: 1580 | F33: 21718 | G33: 36956.8 | H33: 36196.67 | I33: 0 | J33: 0 | K33: 401.78 | L33: 358.35
A34: MM | B34: 46049 | C34: 2242 | D34: XXX-9999 | E34: 1581 | F34: 26833 | G34: 45660.82 | H34: 43961.4 | I34: 0 | J34: 0 | K34: 509.83 | L34: 1189.6
A35: MM | B35: 46049 | C35: 2243 | D35: XXX-9999 | E35: 1581/1593/1594 | F35: 11449 | G35: 19482.38 | H35: 18375.65 | I35: 0 | J35: 0 | K35: 183.18 | L35: 923.55
A36: MM | B36: 46052 | C36: 2227 | D36: XXX-9999 | E36: 1575 | F36: 38399 | G36: 69118.2 | H36: 66110.28 | I36: 0 | J36: 0 | K36: 539.89 | L36: 2468.03
A37: MM | B37: 46052 | C37: 2228 | D37: XXX-9999 | E37: 1578/1582/1583/1584 | F37: 798 | G37: 1436.4 | H37: 1373.89 | I37: 0 | J37: 0 | K37: 11.22 | L37: 51.29
A38: MM | B38: 46052 | C38: 2244 | D38: XXX-9999 | E38: 1581 | F38: 3736 | G38: 6195.53 | H38: 5996.28 | I38: 0 | J38: 0 | K38: 59.78 | L38: 139.48
A39: MM | B39: 46052 | C39: 2245 | D39: XXX-9999 | E39: 1592 | F39: 50340 | G39: 83480.5 | H39: 80795.7 | I39: 0 | J39: 0 | K39: 805.44 | L39: 1879.36
A40: MM | B40: 46052 | C40: 2250 | D40: XXX-9999 | E40: 1578 | F40: 5924 | G40: 9823.97 | H40: 9873.33 | I40: 0 | J40: 0 | K40: 109.59 | L40: -158.96
A41: MM | B41: 46052 | C41: 2251 | D41: XXX-9999 | E41: 1578 | F41: 34453 | G41: 58857.21 | H41: 57421.67 | I41: 0 | J41: 0 | K41: 637.38 | L41: 798.16
A42: MM | B42: 46062 | C42: 2255 | D42: XXX-9999 | E42: /1599 | F42: 39195 | G42: 61029.69 | H42: 51110.28 | I42: 0 | J42: 0 | K42: 0 | L42: 9919.41
A43: MM | B43: 46062 | C43: 2256 | D43: XXX-9999 | E43: /1600 | F43: 51446 | G43: 80105.45 | H43: 67085.58 | I43: 0 | J43: 0 | K43: 0 | L43: 13019.87
A44: MM | B44: 46062 | C44: 2257 | D44: XXX-9999 | E44: /1601 | F44: 50922 | G44: 79289.54 | H44: 66402.29 | I44: 0 | J44: 0 | K44: 0 | L44: 12887.25
A45: MM | B45: 46062 | C45: 2258 | D45: XXX-9999 | E45: /1602 | F45: 60454 | G45: 94131.61 | H45: 78832.02 | I45: 0 | J45: 0 | K45: 0 | L45: 15299.6
A46: MM | B46: 46062 | C46: 2259 | D46: XXX-9999 | E46: /1603 | F46: 41454 | G46: 64547.13 | H46: 54056.02 | I46: 0 | J46: 0 | K46: 0 | L46: 10491.11
A47: MM | B47: 46062 | C47: 2260 | D47: XXX-9999 | E47: 1604 | F47: 48878 | G47: 76106.87 | H47: 63736.91 | I47: 0 | J47: 0 | K47: 0 | L47: 12369.96
...
